<?xml version="1.0" encoding="utf-8"?>
<!-- =================================================================================== -->
<!-- |    This document was autogenerated by xacro from toy_car_3_integration.urdf.xacro | -->
<!-- |    EDITING THIS FILE BY HAND IS NOT RECOMMENDED                                 | -->
<!-- =================================================================================== -->
<!-- Name your robot here -->
<robot name="">
  <link name="base_link">
    <inertial>
      <origin rpy="0 0 0" xyz="0.0953137510067839 0 -0.101443848109706"/>
      <mass value="90.4863171622024"/>
      <inertia ixx="2.31734101461935" ixy="9.40606923907818E-17" ixz="0.534422646160281" iyy="7.29012414676684" iyz="8.33231985741877E-18" izz="8.86465995750526"/>
    </inertial>
    <visual>
      <origin rpy="0 0 0" xyz="0 0 0"/>
      <geometry>
        <mesh filename="package://toy_car_3/meshes/base_link.STL"/>
      </geometry>
      <material name="">
        <color rgba="0.792156862745098 0.819607843137255 0.933333333333333 1"/>
      </material>
    </visual>
    <collision>
      <origin rpy="0 0 0" xyz="0 0 0"/>
      <geometry>
        <mesh filename="package://toy_car_3/meshes/base_link.STL"/>
      </geometry>
    </collision>
  </link>
  <link name="BR_coord">
    <inertial>
      <origin rpy="0 0 0" xyz="-1.1102E-16 0.047495 -1.4572E-16"/>
      <mass value="2.8186"/>
      <inertia ixx="0.009636" ixy="7.9039E-20" ixz="7.1367E-20" iyy="0.013006" iyz="9.4932E-19" izz="0.009636"/>
    </inertial>
    <visual>
      <origin rpy="0 0 0" xyz="0 0 0"/>
      <geometry>
        <mesh filename="package://toy_car_3/meshes/BR_coord.STL"/>
      </geometry>
      <material name="">
        <color rgba="0.79216 0.81961 0.93333 1"/>
      </material>
    </visual>
    <collision>
      <origin rpy="0 0 0" xyz="0 0 0"/>
      <geometry>
        <mesh filename="package://toy_car_3/meshes/BR_coord.STL"/>
      </geometry>
    </collision>
  </link>
  <joint name="BR_coord" type="continuous">
    <origin rpy="0 0 0" xyz="-0.20624 -0.3302 -0.14111"/>
    <parent link="base_link"/>
    <child link="BR_coord"/>
    <axis xyz="0 1 0"/>
    <limit effort="1" velocity="1"/>
  </joint>
  <link name="BL_wheel">
    <inertial>
      <origin rpy="0 0 0" xyz="-1.1102E-16 -0.047495 6.9389E-18"/>
      <mass value="2.8186"/>
      <inertia ixx="0.009636" ixy="2.8579E-19" ixz="-2.5413E-35" iyy="0.013006" iyz="-2.2429E-35" izz="0.009636"/>
    </inertial>
    <visual>
      <origin rpy="0 0 0" xyz="0 0 0"/>
      <geometry>
        <mesh filename="package://toy_car_3/meshes/BL_wheel.STL"/>
      </geometry>
      <material name="">
        <color rgba="0.79216 0.81961 0.93333 1"/>
      </material>
    </visual>
    <collision>
      <origin rpy="0 0 0" xyz="0 0 0"/>
      <geometry>
        <mesh filename="package://toy_car_3/meshes/BL_wheel.STL"/>
      </geometry>
    </collision>
  </link>
  <joint name="BL_joint" type="continuous">
    <origin rpy="0 0 0" xyz="-0.20624 0.3302 -0.14111"/>
    <parent link="base_link"/>
    <child link="BL_wheel"/>
    <axis xyz="0 1 0"/>
    <limit effort="1" velocity="1"/>
  </joint>
  <link name="FL_wheel">
    <inertial>
      <origin rpy="0 0 0" xyz="0 -0.047495 6.9389E-18"/>
      <mass value="2.8186"/>
      <inertia ixx="0.009636" ixy="2.8579E-19" ixz="-2.5413E-35" iyy="0.013006" iyz="-2.2429E-35" izz="0.009636"/>
    </inertial>
    <visual>
      <origin rpy="0 0 0" xyz="0 0 0"/>
      <geometry>
        <mesh filename="package://toy_car_3/meshes/FL_wheel.STL"/>
      </geometry>
      <material name="">
        <color rgba="0.79216 0.81961 0.93333 1"/>
      </material>
    </visual>
    <collision>
      <origin rpy="0 0 0" xyz="0 0 0"/>
      <geometry>
        <mesh filename="package://toy_car_3/meshes/FL_wheel.STL"/>
      </geometry>
    </collision>
  </link>
  <joint name="FL_joint" type="continuous">
    <origin rpy="0 0 0" xyz="0.30176 0.3302 -0.14111"/>
    <parent link="base_link"/>
    <child link="FL_wheel"/>
    <axis xyz="0 1 0"/>
    <limit effort="1" velocity="1"/>
  </joint>
  <link name="FR_wheel">
    <inertial>
      <origin rpy="0 0 0" xyz="-1.3878E-17 0.047495 6.9389E-18"/>
      <mass value="2.8186"/>
      <inertia ixx="0.009636" ixy="2.8528E-19" ixz="-1.0318E-18" iyy="0.013006" iyz="-1.2618E-19" izz="0.009636"/>
    </inertial>
    <visual>
      <origin rpy="0 0 0" xyz="0 0 0"/>
      <geometry>
        <mesh filename="package://toy_car_3/meshes/FR_wheel.STL"/>
      </geometry>
      <material name="">
        <color rgba="0.79216 0.81961 0.93333 1"/>
      </material>
    </visual>
    <collision>
      <origin rpy="0 0 0" xyz="0 0 0"/>
      <geometry>
        <mesh filename="package://toy_car_3/meshes/FR_wheel.STL"/>
      </geometry>
    </collision>
  </link>
  <joint name="FR_joint" type="continuous">
    <origin rpy="0 0 0" xyz="0.30176 -0.3302 -0.14111"/>
    <parent link="base_link"/>
    <child link="FR_wheel"/>
    <axis xyz="0 1 0"/>
    <limit effort="1" velocity="1"/>
  </joint>
  <gazebo reference="base_link">
    <material>Gazebo/Red</material>
  </gazebo>
  <link name="base_laser">
    <inertial>
      <origin rpy="0 0 0" xyz="-0.00029774 0.0066667 0.00013047"/>
      <mass value="0.15717"/>
      <inertia ixx="6.7885E-05" ixy="-1.3987E-07" ixz="-8.1554E-07" iyy="0.00013173" iyz="-9.0932E-08" izz="7.1972E-05"/>
    </inertial>
    <visual>
      <origin rpy="0 0 0" xyz="0 0 0"/>
      <geometry>
        <mesh filename="package://toy_car_3/meshes/ydlidar.dae"/>
      </geometry>
      <material name="">
        <color rgba="0.64706 0.61961 0.58824 1"/>
      </material>
    </visual>
    <collision>
      <origin rpy="0 0 0" xyz="0 0 0"/>
      <geometry>
        <mesh filename="package://toy_car_3/meshes/ydlidar.dae"/>
      </geometry>
    </collision>
  </link>
  <link name="laser_frame">
    <inertial>
      <origin rpy="0 0 0" xyz="-0.00036659 0.00064155 -0.00027052"/>
      <mass value="0.25482"/>
      <inertia ixx="8.9194E-05" ixy="1.8116E-07" ixz="3.6435E-08" iyy="0.00018279" iyz="2.423E-07" izz="0.00011103"/>
    </inertial>
    <!--visual>
      <origin
        xyz="0 0 0"
        rpy="0 0 0" />
      <geometry>
        <mesh
          filename="package://toy_car_3/meshes/ydlidar.dae" />
      </geometry>
      <material
        name="">
        <color
          rgba="0.64706 0.61961 0.58824 1" />
      </material>
    </visual-->
    <!--collision>
      <origin
        xyz="0 0 0"
        rpy="0 0 0" />
      <geometry>
        <mesh
          filename="package://toy_car_3/meshes/ydlidar.dae" />
      </geometry>
    </collision-->
  </link>
  <joint name="laser_joint" type="fixed">
    <origin rpy="0 0 0" xyz="0 0 0.03172"/>
    <parent link="base_laser"/>
    <child link="laser_frame"/>
    <axis xyz="0 0 0"/>
  </joint>
  <!-- Add your gazebo sensors here -->
  <!-- gazebo_ydlidar.xml -->
  <!-- <gazebo reference="laser">
    <sensor:ray name="laser">
      <rayCount>180</rayCount>
      <rangeCount>180</rangeCount>
      <laserCount>1</laserCount>

      <origin>0.0 0.0 0.0</origin>
      <displayRays>false</displayRays>

      <minAngle>-130</minAngle>
      <maxAngle>130</maxAngle>

      <minRange>0.08</minRange>
      <maxRange>10.0</maxRange>
      <resRange>0.01</resRange>
      <updateRate>20</updateRate>
      <controller:gazebo_ros_laser name="gazebo_ros_laser_controller" plugin="libgazebo_ros_laser.so">
    <gaussianNoise>0.005</gaussianNoise>
    <alwaysOn>true</alwaysOn>
    <updateRate>20</updateRate>
    <topicName>scan</topicName>
    <frameName>laser</frameName>
    <interface:laser name="gazebo_ros_laser_iface" />
      </controller:gazebo_ros_laser>
    </sensor:ray>
  </gazebo> -->
  <gazebo reference="base_laser">
    <!-- <gravity>true</gravity> -->
    <!-- Gazebo has fixed set of Sensors types. Check them out here <> -->
    <sensor name="laser" type="ray">
      <!-- Add in your sensor characteristics -->
      <pose> 0 0 0 0 0 0 </pose>
      <visualise>true</visualise>
      <update_rate>40</update_rate>
      <!-- <always_on>true</always_on> -->
      <ray>
        <scan>
          <horizontal>
            <samples>720</samples>
            <resolution>1</resolution>
            <min_angle>-1.570796</min_angle>
            <max_angle>1.570796</max_angle>
          </horizontal>
        </scan>
        <range>
          <min>0.10</min>
          <max>30.0</max>
          <resolution>0.01</resolution>
        </range>
        <noise>
          <type>gaussian</type>
          <mean>0.0</mean>
          <stddev>0.01</stddev>
        </noise>
      </ray>
      <plugin filename="libgazebo_ros_laser.so" name="gazebo_ros_head_hokuyo_controller">
        <!-- Use topic name as /my_robot/scan -->
        <topicName/>
        <frameName>laser_frame</frameName>
      </plugin>
    </sensor>
  </gazebo>
  <!--  Gazebo plugin for control here is already added for you -->
  <gazebo>
    <plugin filename="libgazebo_ros_control.so" name="gazebo_ros_control">
      <robotNamespace>/simple_car</robotNamespace>
      <robotSimType>gazebo_ros_control/DefaultRobotHWSim</robotSimType>
      <legacyModeNS>true</legacyModeNS>
    </plugin>
  </gazebo>
  <!-- Create a joint between your robot and sensor -->
  <!-- Kavya -->
  <joint name="laser_joint_bot" type="fixed">
    <origin rpy="0 0 0" xyz="-0.065 0 0.075"/>
    <parent link="base_link"/>
    <child link="base_laser"/>
  </joint>
  <!-- Kavya -->
</robot>
